2022-10-02 18:38:57,721 — api.app — ERROR —log_exception:1741 — Exception on / [GET]
Traceback (most recent call last):
  File "/Users/marcotulio/Documents/git/flask_api/env/lib/python3.8/site-packages/flask/app.py", line 2525, in wsgi_app
    response = self.full_dispatch_request()
  File "/Users/marcotulio/Documents/git/flask_api/env/lib/python3.8/site-packages/flask/app.py", line 1822, in full_dispatch_request
    rv = self.handle_user_exception(e)
  File "/Users/marcotulio/Documents/git/flask_api/env/lib/python3.8/site-packages/flask/app.py", line 1820, in full_dispatch_request
    rv = self.dispatch_request()
  File "/Users/marcotulio/Documents/git/flask_api/env/lib/python3.8/site-packages/flask/app.py", line 1796, in dispatch_request
    return self.ensure_sync(self.view_functions[rule.endpoint])(**view_args)
  File "/Users/marcotulio/Documents/git/flask_api/packages/ml_api/api/controller.py", line 18, in home
    return render_template('home.html')
  File "/Users/marcotulio/Documents/git/flask_api/env/lib/python3.8/site-packages/flask/templating.py", line 147, in render_template
    return _render(app, template, context)
  File "/Users/marcotulio/Documents/git/flask_api/env/lib/python3.8/site-packages/flask/templating.py", line 130, in _render
    rv = template.render(context)
  File "/Users/marcotulio/Documents/git/flask_api/env/lib/python3.8/site-packages/jinja2/environment.py", line 1301, in render
    self.environment.handle_exception()
  File "/Users/marcotulio/Documents/git/flask_api/env/lib/python3.8/site-packages/jinja2/environment.py", line 936, in handle_exception
    raise rewrite_traceback_stack(source=source)
  File "/Users/marcotulio/Documents/git/flask_api/packages/ml_api/api/templates/home.html", line 20, in top-level template code
    <form action="{{ url_for('predict/regression')}}"method="post">
  File "/Users/marcotulio/Documents/git/flask_api/env/lib/python3.8/site-packages/flask/app.py", line 2031, in url_for
    return self.handle_url_build_error(error, endpoint, values)
  File "/Users/marcotulio/Documents/git/flask_api/env/lib/python3.8/site-packages/flask/app.py", line 2020, in url_for
    rv = url_adapter.build(  # type: ignore[union-attr]
  File "/Users/marcotulio/Documents/git/flask_api/env/lib/python3.8/site-packages/werkzeug/routing/map.py", line 917, in build
    raise BuildError(endpoint, values, method, self)
werkzeug.routing.exceptions.BuildError: Could not build url for endpoint 'predict/regression'. Did you mean 'prediction_app.version' instead?
2022-10-02 18:40:09,985 — api.app — ERROR —log_exception:1741 — Exception on / [GET]
Traceback (most recent call last):
  File "/Users/marcotulio/Documents/git/flask_api/env/lib/python3.8/site-packages/flask/app.py", line 2525, in wsgi_app
    response = self.full_dispatch_request()
  File "/Users/marcotulio/Documents/git/flask_api/env/lib/python3.8/site-packages/flask/app.py", line 1822, in full_dispatch_request
    rv = self.handle_user_exception(e)
  File "/Users/marcotulio/Documents/git/flask_api/env/lib/python3.8/site-packages/flask/app.py", line 1820, in full_dispatch_request
    rv = self.dispatch_request()
  File "/Users/marcotulio/Documents/git/flask_api/env/lib/python3.8/site-packages/flask/app.py", line 1796, in dispatch_request
    return self.ensure_sync(self.view_functions[rule.endpoint])(**view_args)
  File "/Users/marcotulio/Documents/git/flask_api/packages/ml_api/api/controller.py", line 18, in home
    return render_template('home.html')
  File "/Users/marcotulio/Documents/git/flask_api/env/lib/python3.8/site-packages/flask/templating.py", line 147, in render_template
    return _render(app, template, context)
  File "/Users/marcotulio/Documents/git/flask_api/env/lib/python3.8/site-packages/flask/templating.py", line 130, in _render
    rv = template.render(context)
  File "/Users/marcotulio/Documents/git/flask_api/env/lib/python3.8/site-packages/jinja2/environment.py", line 1301, in render
    self.environment.handle_exception()
  File "/Users/marcotulio/Documents/git/flask_api/env/lib/python3.8/site-packages/jinja2/environment.py", line 936, in handle_exception
    raise rewrite_traceback_stack(source=source)
  File "/Users/marcotulio/Documents/git/flask_api/packages/ml_api/api/templates/home.html", line 20, in top-level template code
    <form action="{{ url_for('predict')}}"method="post">
  File "/Users/marcotulio/Documents/git/flask_api/env/lib/python3.8/site-packages/flask/app.py", line 2031, in url_for
    return self.handle_url_build_error(error, endpoint, values)
  File "/Users/marcotulio/Documents/git/flask_api/env/lib/python3.8/site-packages/flask/app.py", line 2020, in url_for
    rv = url_adapter.build(  # type: ignore[union-attr]
  File "/Users/marcotulio/Documents/git/flask_api/env/lib/python3.8/site-packages/werkzeug/routing/map.py", line 917, in build
    raise BuildError(endpoint, values, method, self)
werkzeug.routing.exceptions.BuildError: Could not build url for endpoint 'predict'. Did you mean 'prediction_app.home' instead?
2022-10-02 18:40:14,362 — api.app — ERROR —log_exception:1741 — Exception on / [GET]
Traceback (most recent call last):
  File "/Users/marcotulio/Documents/git/flask_api/env/lib/python3.8/site-packages/flask/app.py", line 2525, in wsgi_app
    response = self.full_dispatch_request()
  File "/Users/marcotulio/Documents/git/flask_api/env/lib/python3.8/site-packages/flask/app.py", line 1822, in full_dispatch_request
    rv = self.handle_user_exception(e)
  File "/Users/marcotulio/Documents/git/flask_api/env/lib/python3.8/site-packages/flask/app.py", line 1820, in full_dispatch_request
    rv = self.dispatch_request()
  File "/Users/marcotulio/Documents/git/flask_api/env/lib/python3.8/site-packages/flask/app.py", line 1796, in dispatch_request
    return self.ensure_sync(self.view_functions[rule.endpoint])(**view_args)
  File "/Users/marcotulio/Documents/git/flask_api/packages/ml_api/api/controller.py", line 18, in home
    return render_template('home.html')
  File "/Users/marcotulio/Documents/git/flask_api/env/lib/python3.8/site-packages/flask/templating.py", line 147, in render_template
    return _render(app, template, context)
  File "/Users/marcotulio/Documents/git/flask_api/env/lib/python3.8/site-packages/flask/templating.py", line 130, in _render
    rv = template.render(context)
  File "/Users/marcotulio/Documents/git/flask_api/env/lib/python3.8/site-packages/jinja2/environment.py", line 1301, in render
    self.environment.handle_exception()
  File "/Users/marcotulio/Documents/git/flask_api/env/lib/python3.8/site-packages/jinja2/environment.py", line 936, in handle_exception
    raise rewrite_traceback_stack(source=source)
  File "/Users/marcotulio/Documents/git/flask_api/packages/ml_api/api/templates/home.html", line 20, in top-level template code
    <form action="{{ url_for('predict')}}"method="post">
  File "/Users/marcotulio/Documents/git/flask_api/env/lib/python3.8/site-packages/flask/app.py", line 2031, in url_for
    return self.handle_url_build_error(error, endpoint, values)
  File "/Users/marcotulio/Documents/git/flask_api/env/lib/python3.8/site-packages/flask/app.py", line 2020, in url_for
    rv = url_adapter.build(  # type: ignore[union-attr]
  File "/Users/marcotulio/Documents/git/flask_api/env/lib/python3.8/site-packages/werkzeug/routing/map.py", line 917, in build
    raise BuildError(endpoint, values, method, self)
werkzeug.routing.exceptions.BuildError: Could not build url for endpoint 'predict'. Did you mean 'prediction_app.home' instead?
2022-10-02 18:40:23,806 — api.app — ERROR —log_exception:1741 — Exception on / [GET]
Traceback (most recent call last):
  File "/Users/marcotulio/Documents/git/flask_api/env/lib/python3.8/site-packages/flask/app.py", line 2525, in wsgi_app
    response = self.full_dispatch_request()
  File "/Users/marcotulio/Documents/git/flask_api/env/lib/python3.8/site-packages/flask/app.py", line 1822, in full_dispatch_request
    rv = self.handle_user_exception(e)
  File "/Users/marcotulio/Documents/git/flask_api/env/lib/python3.8/site-packages/flask/app.py", line 1820, in full_dispatch_request
    rv = self.dispatch_request()
  File "/Users/marcotulio/Documents/git/flask_api/env/lib/python3.8/site-packages/flask/app.py", line 1796, in dispatch_request
    return self.ensure_sync(self.view_functions[rule.endpoint])(**view_args)
  File "/Users/marcotulio/Documents/git/flask_api/packages/ml_api/api/controller.py", line 18, in home
    return render_template('home.html')
  File "/Users/marcotulio/Documents/git/flask_api/env/lib/python3.8/site-packages/flask/templating.py", line 147, in render_template
    return _render(app, template, context)
  File "/Users/marcotulio/Documents/git/flask_api/env/lib/python3.8/site-packages/flask/templating.py", line 130, in _render
    rv = template.render(context)
  File "/Users/marcotulio/Documents/git/flask_api/env/lib/python3.8/site-packages/jinja2/environment.py", line 1301, in render
    self.environment.handle_exception()
  File "/Users/marcotulio/Documents/git/flask_api/env/lib/python3.8/site-packages/jinja2/environment.py", line 936, in handle_exception
    raise rewrite_traceback_stack(source=source)
  File "/Users/marcotulio/Documents/git/flask_api/packages/ml_api/api/templates/home.html", line 20, in top-level template code
    <form action="{{ url_for('predict')}}"method="post">
  File "/Users/marcotulio/Documents/git/flask_api/env/lib/python3.8/site-packages/flask/app.py", line 2031, in url_for
    return self.handle_url_build_error(error, endpoint, values)
  File "/Users/marcotulio/Documents/git/flask_api/env/lib/python3.8/site-packages/flask/app.py", line 2020, in url_for
    rv = url_adapter.build(  # type: ignore[union-attr]
  File "/Users/marcotulio/Documents/git/flask_api/env/lib/python3.8/site-packages/werkzeug/routing/map.py", line 917, in build
    raise BuildError(endpoint, values, method, self)
werkzeug.routing.exceptions.BuildError: Could not build url for endpoint 'predict'. Did you mean 'prediction_app.home' instead?
2022-10-02 18:40:29,587 — api.app — ERROR —log_exception:1741 — Exception on / [GET]
Traceback (most recent call last):
  File "/Users/marcotulio/Documents/git/flask_api/env/lib/python3.8/site-packages/flask/app.py", line 2525, in wsgi_app
    response = self.full_dispatch_request()
  File "/Users/marcotulio/Documents/git/flask_api/env/lib/python3.8/site-packages/flask/app.py", line 1822, in full_dispatch_request
    rv = self.handle_user_exception(e)
  File "/Users/marcotulio/Documents/git/flask_api/env/lib/python3.8/site-packages/flask/app.py", line 1820, in full_dispatch_request
    rv = self.dispatch_request()
  File "/Users/marcotulio/Documents/git/flask_api/env/lib/python3.8/site-packages/flask/app.py", line 1796, in dispatch_request
    return self.ensure_sync(self.view_functions[rule.endpoint])(**view_args)
  File "/Users/marcotulio/Documents/git/flask_api/packages/ml_api/api/controller.py", line 18, in home
    return render_template('home.html')
  File "/Users/marcotulio/Documents/git/flask_api/env/lib/python3.8/site-packages/flask/templating.py", line 147, in render_template
    return _render(app, template, context)
  File "/Users/marcotulio/Documents/git/flask_api/env/lib/python3.8/site-packages/flask/templating.py", line 130, in _render
    rv = template.render(context)
  File "/Users/marcotulio/Documents/git/flask_api/env/lib/python3.8/site-packages/jinja2/environment.py", line 1301, in render
    self.environment.handle_exception()
  File "/Users/marcotulio/Documents/git/flask_api/env/lib/python3.8/site-packages/jinja2/environment.py", line 936, in handle_exception
    raise rewrite_traceback_stack(source=source)
  File "/Users/marcotulio/Documents/git/flask_api/packages/ml_api/api/templates/home.html", line 20, in top-level template code
    <form action="{{ url_for('predict')}}"method="post">
  File "/Users/marcotulio/Documents/git/flask_api/env/lib/python3.8/site-packages/flask/app.py", line 2031, in url_for
    return self.handle_url_build_error(error, endpoint, values)
  File "/Users/marcotulio/Documents/git/flask_api/env/lib/python3.8/site-packages/flask/app.py", line 2020, in url_for
    rv = url_adapter.build(  # type: ignore[union-attr]
  File "/Users/marcotulio/Documents/git/flask_api/env/lib/python3.8/site-packages/werkzeug/routing/map.py", line 917, in build
    raise BuildError(endpoint, values, method, self)
werkzeug.routing.exceptions.BuildError: Could not build url for endpoint 'predict'. Did you mean 'prediction_app.home' instead?
2022-10-02 18:49:45,961 — api.app — ERROR —log_exception:1741 — Exception on / [GET]
Traceback (most recent call last):
  File "/Users/marcotulio/Documents/git/flask_api/env/lib/python3.8/site-packages/flask/app.py", line 2525, in wsgi_app
    response = self.full_dispatch_request()
  File "/Users/marcotulio/Documents/git/flask_api/env/lib/python3.8/site-packages/flask/app.py", line 1822, in full_dispatch_request
    rv = self.handle_user_exception(e)
  File "/Users/marcotulio/Documents/git/flask_api/env/lib/python3.8/site-packages/flask/app.py", line 1820, in full_dispatch_request
    rv = self.dispatch_request()
  File "/Users/marcotulio/Documents/git/flask_api/env/lib/python3.8/site-packages/flask/app.py", line 1796, in dispatch_request
    return self.ensure_sync(self.view_functions[rule.endpoint])(**view_args)
  File "/Users/marcotulio/Documents/git/flask_api/packages/ml_api/api/controller.py", line 18, in home
    return render_template('home.html')
  File "/Users/marcotulio/Documents/git/flask_api/env/lib/python3.8/site-packages/flask/templating.py", line 147, in render_template
    return _render(app, template, context)
  File "/Users/marcotulio/Documents/git/flask_api/env/lib/python3.8/site-packages/flask/templating.py", line 130, in _render
    rv = template.render(context)
  File "/Users/marcotulio/Documents/git/flask_api/env/lib/python3.8/site-packages/jinja2/environment.py", line 1301, in render
    self.environment.handle_exception()
  File "/Users/marcotulio/Documents/git/flask_api/env/lib/python3.8/site-packages/jinja2/environment.py", line 936, in handle_exception
    raise rewrite_traceback_stack(source=source)
  File "/Users/marcotulio/Documents/git/flask_api/packages/ml_api/api/templates/home.html", line 20, in top-level template code
    <form action="{{ url_for('predict')}}"method="post">
  File "/Users/marcotulio/Documents/git/flask_api/env/lib/python3.8/site-packages/flask/app.py", line 2031, in url_for
    return self.handle_url_build_error(error, endpoint, values)
  File "/Users/marcotulio/Documents/git/flask_api/env/lib/python3.8/site-packages/flask/app.py", line 2020, in url_for
    rv = url_adapter.build(  # type: ignore[union-attr]
  File "/Users/marcotulio/Documents/git/flask_api/env/lib/python3.8/site-packages/werkzeug/routing/map.py", line 917, in build
    raise BuildError(endpoint, values, method, self)
werkzeug.routing.exceptions.BuildError: Could not build url for endpoint 'predict'. Did you mean 'prediction_app.home' instead?
2022-10-02 18:50:50,664 — api.app — ERROR —log_exception:1741 — Exception on / [GET]
Traceback (most recent call last):
  File "/Users/marcotulio/Documents/git/flask_api/env/lib/python3.8/site-packages/flask/app.py", line 2525, in wsgi_app
    response = self.full_dispatch_request()
  File "/Users/marcotulio/Documents/git/flask_api/env/lib/python3.8/site-packages/flask/app.py", line 1822, in full_dispatch_request
    rv = self.handle_user_exception(e)
  File "/Users/marcotulio/Documents/git/flask_api/env/lib/python3.8/site-packages/flask/app.py", line 1820, in full_dispatch_request
    rv = self.dispatch_request()
  File "/Users/marcotulio/Documents/git/flask_api/env/lib/python3.8/site-packages/flask/app.py", line 1796, in dispatch_request
    return self.ensure_sync(self.view_functions[rule.endpoint])(**view_args)
  File "/Users/marcotulio/Documents/git/flask_api/packages/ml_api/api/controller.py", line 18, in home
    return render_template('home.html')
  File "/Users/marcotulio/Documents/git/flask_api/env/lib/python3.8/site-packages/flask/templating.py", line 147, in render_template
    return _render(app, template, context)
  File "/Users/marcotulio/Documents/git/flask_api/env/lib/python3.8/site-packages/flask/templating.py", line 130, in _render
    rv = template.render(context)
  File "/Users/marcotulio/Documents/git/flask_api/env/lib/python3.8/site-packages/jinja2/environment.py", line 1301, in render
    self.environment.handle_exception()
  File "/Users/marcotulio/Documents/git/flask_api/env/lib/python3.8/site-packages/jinja2/environment.py", line 936, in handle_exception
    raise rewrite_traceback_stack(source=source)
  File "/Users/marcotulio/Documents/git/flask_api/packages/ml_api/api/templates/home.html", line 20, in top-level template code
    <form action="{{ url_for('predict')}}"method="post">
  File "/Users/marcotulio/Documents/git/flask_api/env/lib/python3.8/site-packages/flask/app.py", line 2031, in url_for
    return self.handle_url_build_error(error, endpoint, values)
  File "/Users/marcotulio/Documents/git/flask_api/env/lib/python3.8/site-packages/flask/app.py", line 2020, in url_for
    rv = url_adapter.build(  # type: ignore[union-attr]
  File "/Users/marcotulio/Documents/git/flask_api/env/lib/python3.8/site-packages/werkzeug/routing/map.py", line 917, in build
    raise BuildError(endpoint, values, method, self)
werkzeug.routing.exceptions.BuildError: Could not build url for endpoint 'predict'. Did you mean 'prediction_app.home' instead?
2022-10-02 18:56:33,351 — api.app — ERROR —log_exception:1741 — Exception on / [GET]
Traceback (most recent call last):
  File "/Users/marcotulio/Documents/git/flask_api/env/lib/python3.8/site-packages/flask/app.py", line 2525, in wsgi_app
    response = self.full_dispatch_request()
  File "/Users/marcotulio/Documents/git/flask_api/env/lib/python3.8/site-packages/flask/app.py", line 1822, in full_dispatch_request
    rv = self.handle_user_exception(e)
  File "/Users/marcotulio/Documents/git/flask_api/env/lib/python3.8/site-packages/flask/app.py", line 1820, in full_dispatch_request
    rv = self.dispatch_request()
  File "/Users/marcotulio/Documents/git/flask_api/env/lib/python3.8/site-packages/flask/app.py", line 1796, in dispatch_request
    return self.ensure_sync(self.view_functions[rule.endpoint])(**view_args)
  File "/Users/marcotulio/Documents/git/flask_api/packages/ml_api/api/controller.py", line 18, in home
    return render_template('home.html')
  File "/Users/marcotulio/Documents/git/flask_api/env/lib/python3.8/site-packages/flask/templating.py", line 147, in render_template
    return _render(app, template, context)
  File "/Users/marcotulio/Documents/git/flask_api/env/lib/python3.8/site-packages/flask/templating.py", line 130, in _render
    rv = template.render(context)
  File "/Users/marcotulio/Documents/git/flask_api/env/lib/python3.8/site-packages/jinja2/environment.py", line 1301, in render
    self.environment.handle_exception()
  File "/Users/marcotulio/Documents/git/flask_api/env/lib/python3.8/site-packages/jinja2/environment.py", line 936, in handle_exception
    raise rewrite_traceback_stack(source=source)
  File "/Users/marcotulio/Documents/git/flask_api/packages/ml_api/api/templates/home.html", line 20, in top-level template code
    <form action="{{ url_for('predict')}}"method="post">
  File "/Users/marcotulio/Documents/git/flask_api/env/lib/python3.8/site-packages/flask/app.py", line 2031, in url_for
    return self.handle_url_build_error(error, endpoint, values)
  File "/Users/marcotulio/Documents/git/flask_api/env/lib/python3.8/site-packages/flask/app.py", line 2020, in url_for
    rv = url_adapter.build(  # type: ignore[union-attr]
  File "/Users/marcotulio/Documents/git/flask_api/env/lib/python3.8/site-packages/werkzeug/routing/map.py", line 917, in build
    raise BuildError(endpoint, values, method, self)
werkzeug.routing.exceptions.BuildError: Could not build url for endpoint 'predict'. Did you mean 'prediction_app.home' instead?
2022-10-04 09:59:18,510 — api.app — ERROR —log_exception:1741 — Exception on / [GET]
Traceback (most recent call last):
  File "/Users/shuck/development/ML_flask_api/env/lib/python3.10/site-packages/flask/app.py", line 2525, in wsgi_app
    response = self.full_dispatch_request()
  File "/Users/shuck/development/ML_flask_api/env/lib/python3.10/site-packages/flask/app.py", line 1822, in full_dispatch_request
    rv = self.handle_user_exception(e)
  File "/Users/shuck/development/ML_flask_api/env/lib/python3.10/site-packages/flask/app.py", line 1820, in full_dispatch_request
    rv = self.dispatch_request()
  File "/Users/shuck/development/ML_flask_api/env/lib/python3.10/site-packages/flask/app.py", line 1796, in dispatch_request
    return self.ensure_sync(self.view_functions[rule.endpoint])(**view_args)
  File "/Users/shuck/development/ML_flask_api/packages/ml_api/api/controller.py", line 18, in home
    return render_template('home.html')
  File "/Users/shuck/development/ML_flask_api/env/lib/python3.10/site-packages/flask/templating.py", line 147, in render_template
    return _render(app, template, context)
  File "/Users/shuck/development/ML_flask_api/env/lib/python3.10/site-packages/flask/templating.py", line 130, in _render
    rv = template.render(context)
  File "/Users/shuck/development/ML_flask_api/env/lib/python3.10/site-packages/jinja2/environment.py", line 1301, in render
    self.environment.handle_exception()
  File "/Users/shuck/development/ML_flask_api/env/lib/python3.10/site-packages/jinja2/environment.py", line 936, in handle_exception
    raise rewrite_traceback_stack(source=source)
  File "/Users/shuck/development/ML_flask_api/packages/ml_api/api/templates/home.html", line 38, in top-level template code
    <button name="number" value="number" onclick="{{console.log('Hello World')}}">Calculate</button>
  File "/Users/shuck/development/ML_flask_api/env/lib/python3.10/site-packages/jinja2/environment.py", line 485, in getattr
    return getattr(obj, attribute)
jinja2.exceptions.UndefinedError: 'console' is undefined
2022-10-04 09:59:23,390 — api.app — ERROR —log_exception:1741 — Exception on / [GET]
Traceback (most recent call last):
  File "/Users/shuck/development/ML_flask_api/env/lib/python3.10/site-packages/flask/app.py", line 2525, in wsgi_app
    response = self.full_dispatch_request()
  File "/Users/shuck/development/ML_flask_api/env/lib/python3.10/site-packages/flask/app.py", line 1822, in full_dispatch_request
    rv = self.handle_user_exception(e)
  File "/Users/shuck/development/ML_flask_api/env/lib/python3.10/site-packages/flask/app.py", line 1820, in full_dispatch_request
    rv = self.dispatch_request()
  File "/Users/shuck/development/ML_flask_api/env/lib/python3.10/site-packages/flask/app.py", line 1796, in dispatch_request
    return self.ensure_sync(self.view_functions[rule.endpoint])(**view_args)
  File "/Users/shuck/development/ML_flask_api/packages/ml_api/api/controller.py", line 18, in home
    return render_template('home.html')
  File "/Users/shuck/development/ML_flask_api/env/lib/python3.10/site-packages/flask/templating.py", line 147, in render_template
    return _render(app, template, context)
  File "/Users/shuck/development/ML_flask_api/env/lib/python3.10/site-packages/flask/templating.py", line 130, in _render
    rv = template.render(context)
  File "/Users/shuck/development/ML_flask_api/env/lib/python3.10/site-packages/jinja2/environment.py", line 1301, in render
    self.environment.handle_exception()
  File "/Users/shuck/development/ML_flask_api/env/lib/python3.10/site-packages/jinja2/environment.py", line 936, in handle_exception
    raise rewrite_traceback_stack(source=source)
  File "/Users/shuck/development/ML_flask_api/packages/ml_api/api/templates/home.html", line 38, in top-level template code
    <button name="number" value="number" onclick="{{console.log('Hello World')}}">Calculate</button>
  File "/Users/shuck/development/ML_flask_api/env/lib/python3.10/site-packages/jinja2/environment.py", line 485, in getattr
    return getattr(obj, attribute)
jinja2.exceptions.UndefinedError: 'console' is undefined
2022-10-04 09:59:41,106 — api.app — ERROR —log_exception:1741 — Exception on / [GET]
Traceback (most recent call last):
  File "/Users/shuck/development/ML_flask_api/env/lib/python3.10/site-packages/flask/app.py", line 2525, in wsgi_app
    response = self.full_dispatch_request()
  File "/Users/shuck/development/ML_flask_api/env/lib/python3.10/site-packages/flask/app.py", line 1822, in full_dispatch_request
    rv = self.handle_user_exception(e)
  File "/Users/shuck/development/ML_flask_api/env/lib/python3.10/site-packages/flask/app.py", line 1820, in full_dispatch_request
    rv = self.dispatch_request()
  File "/Users/shuck/development/ML_flask_api/env/lib/python3.10/site-packages/flask/app.py", line 1796, in dispatch_request
    return self.ensure_sync(self.view_functions[rule.endpoint])(**view_args)
  File "/Users/shuck/development/ML_flask_api/packages/ml_api/api/controller.py", line 18, in home
    return render_template('home.html')
  File "/Users/shuck/development/ML_flask_api/env/lib/python3.10/site-packages/flask/templating.py", line 147, in render_template
    return _render(app, template, context)
  File "/Users/shuck/development/ML_flask_api/env/lib/python3.10/site-packages/flask/templating.py", line 130, in _render
    rv = template.render(context)
  File "/Users/shuck/development/ML_flask_api/env/lib/python3.10/site-packages/jinja2/environment.py", line 1301, in render
    self.environment.handle_exception()
  File "/Users/shuck/development/ML_flask_api/env/lib/python3.10/site-packages/jinja2/environment.py", line 936, in handle_exception
    raise rewrite_traceback_stack(source=source)
  File "/Users/shuck/development/ML_flask_api/packages/ml_api/api/templates/home.html", line 38, in top-level template code
    <button name="number" value="number" onclick={{console.log('Hello World')}}>Calculate</button>
  File "/Users/shuck/development/ML_flask_api/env/lib/python3.10/site-packages/jinja2/environment.py", line 485, in getattr
    return getattr(obj, attribute)
jinja2.exceptions.UndefinedError: 'console' is undefined
2022-10-04 09:59:43,086 — api.app — ERROR —log_exception:1741 — Exception on / [GET]
Traceback (most recent call last):
  File "/Users/shuck/development/ML_flask_api/env/lib/python3.10/site-packages/flask/app.py", line 2525, in wsgi_app
    response = self.full_dispatch_request()
  File "/Users/shuck/development/ML_flask_api/env/lib/python3.10/site-packages/flask/app.py", line 1822, in full_dispatch_request
    rv = self.handle_user_exception(e)
  File "/Users/shuck/development/ML_flask_api/env/lib/python3.10/site-packages/flask/app.py", line 1820, in full_dispatch_request
    rv = self.dispatch_request()
  File "/Users/shuck/development/ML_flask_api/env/lib/python3.10/site-packages/flask/app.py", line 1796, in dispatch_request
    return self.ensure_sync(self.view_functions[rule.endpoint])(**view_args)
  File "/Users/shuck/development/ML_flask_api/packages/ml_api/api/controller.py", line 18, in home
    return render_template('home.html')
  File "/Users/shuck/development/ML_flask_api/env/lib/python3.10/site-packages/flask/templating.py", line 147, in render_template
    return _render(app, template, context)
  File "/Users/shuck/development/ML_flask_api/env/lib/python3.10/site-packages/flask/templating.py", line 130, in _render
    rv = template.render(context)
  File "/Users/shuck/development/ML_flask_api/env/lib/python3.10/site-packages/jinja2/environment.py", line 1301, in render
    self.environment.handle_exception()
  File "/Users/shuck/development/ML_flask_api/env/lib/python3.10/site-packages/jinja2/environment.py", line 936, in handle_exception
    raise rewrite_traceback_stack(source=source)
  File "/Users/shuck/development/ML_flask_api/packages/ml_api/api/templates/home.html", line 38, in top-level template code
    <button name="number" value="number" onclick={{console.log('Hello World')}}>Calculate</button>
  File "/Users/shuck/development/ML_flask_api/env/lib/python3.10/site-packages/jinja2/environment.py", line 485, in getattr
    return getattr(obj, attribute)
jinja2.exceptions.UndefinedError: 'console' is undefined
2022-10-04 11:17:29,101 — api.app — ERROR —log_exception:1741 — Exception on /predict [POST]
Traceback (most recent call last):
  File "/Users/shuck/development/ML_flask_api/env/lib/python3.10/site-packages/flask/app.py", line 2525, in wsgi_app
    response = self.full_dispatch_request()
  File "/Users/shuck/development/ML_flask_api/env/lib/python3.10/site-packages/flask/app.py", line 1823, in full_dispatch_request
    return self.finalize_request(rv)
  File "/Users/shuck/development/ML_flask_api/env/lib/python3.10/site-packages/flask/app.py", line 1842, in finalize_request
    response = self.make_response(rv)
  File "/Users/shuck/development/ML_flask_api/env/lib/python3.10/site-packages/flask/app.py", line 2170, in make_response
    raise TypeError(
TypeError: The view function did not return a valid response. The return type must be a string, dict, list, tuple with headers or status, Response instance, or WSGI callable, but it was a int.
2022-10-04 11:19:45,071 — api.app — ERROR —log_exception:1741 — Exception on /predict [POST]
Traceback (most recent call last):
  File "/Users/shuck/development/ML_flask_api/env/lib/python3.10/site-packages/flask/app.py", line 2525, in wsgi_app
    response = self.full_dispatch_request()
  File "/Users/shuck/development/ML_flask_api/env/lib/python3.10/site-packages/flask/app.py", line 1823, in full_dispatch_request
    return self.finalize_request(rv)
  File "/Users/shuck/development/ML_flask_api/env/lib/python3.10/site-packages/flask/app.py", line 1842, in finalize_request
    response = self.make_response(rv)
  File "/Users/shuck/development/ML_flask_api/env/lib/python3.10/site-packages/flask/app.py", line 2170, in make_response
    raise TypeError(
TypeError: The view function did not return a valid response. The return type must be a string, dict, list, tuple with headers or status, Response instance, or WSGI callable, but it was a int.
2022-10-04 11:19:56,254 — api.app — ERROR —log_exception:1741 — Exception on /predict [POST]
Traceback (most recent call last):
  File "/Users/shuck/development/ML_flask_api/env/lib/python3.10/site-packages/flask/app.py", line 2525, in wsgi_app
    response = self.full_dispatch_request()
  File "/Users/shuck/development/ML_flask_api/env/lib/python3.10/site-packages/flask/app.py", line 1823, in full_dispatch_request
    return self.finalize_request(rv)
  File "/Users/shuck/development/ML_flask_api/env/lib/python3.10/site-packages/flask/app.py", line 1842, in finalize_request
    response = self.make_response(rv)
  File "/Users/shuck/development/ML_flask_api/env/lib/python3.10/site-packages/flask/app.py", line 2170, in make_response
    raise TypeError(
TypeError: The view function did not return a valid response. The return type must be a string, dict, list, tuple with headers or status, Response instance, or WSGI callable, but it was a int.
2022-10-04 11:37:29,146 — api.app — ERROR —log_exception:1741 — Exception on /predict [POST]
Traceback (most recent call last):
  File "/Users/shuck/development/ML_flask_api/env/lib/python3.10/site-packages/flask/app.py", line 2525, in wsgi_app
    response = self.full_dispatch_request()
  File "/Users/shuck/development/ML_flask_api/env/lib/python3.10/site-packages/flask/app.py", line 1823, in full_dispatch_request
    return self.finalize_request(rv)
  File "/Users/shuck/development/ML_flask_api/env/lib/python3.10/site-packages/flask/app.py", line 1842, in finalize_request
    response = self.make_response(rv)
  File "/Users/shuck/development/ML_flask_api/env/lib/python3.10/site-packages/flask/app.py", line 2153, in make_response
    rv = self.json.response(rv)
  File "/Users/shuck/development/ML_flask_api/env/lib/python3.10/site-packages/flask/json/provider.py", line 309, in response
    f"{self.dumps(obj, **dump_args)}\n", mimetype=mimetype
  File "/Users/shuck/development/ML_flask_api/env/lib/python3.10/site-packages/flask/json/provider.py", line 230, in dumps
    return json.dumps(obj, **kwargs)
  File "/opt/homebrew/Cellar/python@3.10/3.10.6_2/Frameworks/Python.framework/Versions/3.10/lib/python3.10/json/__init__.py", line 238, in dumps
    **kw).encode(obj)
  File "/opt/homebrew/Cellar/python@3.10/3.10.6_2/Frameworks/Python.framework/Versions/3.10/lib/python3.10/json/encoder.py", line 199, in encode
    chunks = self.iterencode(o, _one_shot=True)
  File "/opt/homebrew/Cellar/python@3.10/3.10.6_2/Frameworks/Python.framework/Versions/3.10/lib/python3.10/json/encoder.py", line 257, in iterencode
    return _iterencode(o, 0)
  File "/Users/shuck/development/ML_flask_api/env/lib/python3.10/site-packages/flask/json/provider.py", line 122, in _default
    raise TypeError(f"Object of type {type(o).__name__} is not JSON serializable")
TypeError: Object of type bytes is not JSON serializable
2022-10-04 11:57:57,972 — api.app — ERROR —log_exception:1741 — Exception on / [GET]
Traceback (most recent call last):
  File "/Users/shuck/development/ML_flask_api/env/lib/python3.10/site-packages/flask/app.py", line 2525, in wsgi_app
    response = self.full_dispatch_request()
  File "/Users/shuck/development/ML_flask_api/env/lib/python3.10/site-packages/flask/app.py", line 1822, in full_dispatch_request
    rv = self.handle_user_exception(e)
  File "/Users/shuck/development/ML_flask_api/env/lib/python3.10/site-packages/flask/app.py", line 1820, in full_dispatch_request
    rv = self.dispatch_request()
  File "/Users/shuck/development/ML_flask_api/env/lib/python3.10/site-packages/flask/app.py", line 1796, in dispatch_request
    return self.ensure_sync(self.view_functions[rule.endpoint])(**view_args)
  File "/Users/shuck/development/ML_flask_api/packages/ml_api/api/controller.py", line 18, in home
    return render_template('home.html')
  File "/Users/shuck/development/ML_flask_api/env/lib/python3.10/site-packages/flask/templating.py", line 146, in render_template
    template = app.jinja_env.get_or_select_template(template_name_or_list)
  File "/Users/shuck/development/ML_flask_api/env/lib/python3.10/site-packages/jinja2/environment.py", line 1081, in get_or_select_template
    return self.get_template(template_name_or_list, parent, globals)
  File "/Users/shuck/development/ML_flask_api/env/lib/python3.10/site-packages/jinja2/environment.py", line 1010, in get_template
    return self._load_template(name, globals)
  File "/Users/shuck/development/ML_flask_api/env/lib/python3.10/site-packages/jinja2/environment.py", line 969, in _load_template
    template = self.loader.load(self, name, self.make_globals(globals))
  File "/Users/shuck/development/ML_flask_api/env/lib/python3.10/site-packages/jinja2/loaders.py", line 138, in load
    code = environment.compile(source, name, filename)
  File "/Users/shuck/development/ML_flask_api/env/lib/python3.10/site-packages/jinja2/environment.py", line 768, in compile
    self.handle_exception(source=source_hint)
  File "/Users/shuck/development/ML_flask_api/env/lib/python3.10/site-packages/jinja2/environment.py", line 936, in handle_exception
    raise rewrite_traceback_stack(source=source)
  File "/Users/shuck/development/ML_flask_api/packages/ml_api/api/templates/home.html", line 15, in template
    {% comment %} fetch(apiUrl).then(response => {
jinja2.exceptions.TemplateSyntaxError: Encountered unknown tag 'comment'.
2022-10-04 11:57:59,605 — api.app — ERROR —log_exception:1741 — Exception on / [GET]
Traceback (most recent call last):
  File "/Users/shuck/development/ML_flask_api/env/lib/python3.10/site-packages/flask/app.py", line 2525, in wsgi_app
    response = self.full_dispatch_request()
  File "/Users/shuck/development/ML_flask_api/env/lib/python3.10/site-packages/flask/app.py", line 1822, in full_dispatch_request
    rv = self.handle_user_exception(e)
  File "/Users/shuck/development/ML_flask_api/env/lib/python3.10/site-packages/flask/app.py", line 1820, in full_dispatch_request
    rv = self.dispatch_request()
  File "/Users/shuck/development/ML_flask_api/env/lib/python3.10/site-packages/flask/app.py", line 1796, in dispatch_request
    return self.ensure_sync(self.view_functions[rule.endpoint])(**view_args)
  File "/Users/shuck/development/ML_flask_api/packages/ml_api/api/controller.py", line 18, in home
    return render_template('home.html')
  File "/Users/shuck/development/ML_flask_api/env/lib/python3.10/site-packages/flask/templating.py", line 146, in render_template
    template = app.jinja_env.get_or_select_template(template_name_or_list)
  File "/Users/shuck/development/ML_flask_api/env/lib/python3.10/site-packages/jinja2/environment.py", line 1081, in get_or_select_template
    return self.get_template(template_name_or_list, parent, globals)
  File "/Users/shuck/development/ML_flask_api/env/lib/python3.10/site-packages/jinja2/environment.py", line 1010, in get_template
    return self._load_template(name, globals)
  File "/Users/shuck/development/ML_flask_api/env/lib/python3.10/site-packages/jinja2/environment.py", line 969, in _load_template
    template = self.loader.load(self, name, self.make_globals(globals))
  File "/Users/shuck/development/ML_flask_api/env/lib/python3.10/site-packages/jinja2/loaders.py", line 138, in load
    code = environment.compile(source, name, filename)
  File "/Users/shuck/development/ML_flask_api/env/lib/python3.10/site-packages/jinja2/environment.py", line 768, in compile
    self.handle_exception(source=source_hint)
  File "/Users/shuck/development/ML_flask_api/env/lib/python3.10/site-packages/jinja2/environment.py", line 936, in handle_exception
    raise rewrite_traceback_stack(source=source)
  File "/Users/shuck/development/ML_flask_api/packages/ml_api/api/templates/home.html", line 15, in template
    {% comment %} fetch(apiUrl).then(response => {
jinja2.exceptions.TemplateSyntaxError: Encountered unknown tag 'comment'.
2022-10-04 11:58:00,290 — api.app — ERROR —log_exception:1741 — Exception on / [GET]
Traceback (most recent call last):
  File "/Users/shuck/development/ML_flask_api/env/lib/python3.10/site-packages/flask/app.py", line 2525, in wsgi_app
    response = self.full_dispatch_request()
  File "/Users/shuck/development/ML_flask_api/env/lib/python3.10/site-packages/flask/app.py", line 1822, in full_dispatch_request
    rv = self.handle_user_exception(e)
  File "/Users/shuck/development/ML_flask_api/env/lib/python3.10/site-packages/flask/app.py", line 1820, in full_dispatch_request
    rv = self.dispatch_request()
  File "/Users/shuck/development/ML_flask_api/env/lib/python3.10/site-packages/flask/app.py", line 1796, in dispatch_request
    return self.ensure_sync(self.view_functions[rule.endpoint])(**view_args)
  File "/Users/shuck/development/ML_flask_api/packages/ml_api/api/controller.py", line 18, in home
    return render_template('home.html')
  File "/Users/shuck/development/ML_flask_api/env/lib/python3.10/site-packages/flask/templating.py", line 146, in render_template
    template = app.jinja_env.get_or_select_template(template_name_or_list)
  File "/Users/shuck/development/ML_flask_api/env/lib/python3.10/site-packages/jinja2/environment.py", line 1081, in get_or_select_template
    return self.get_template(template_name_or_list, parent, globals)
  File "/Users/shuck/development/ML_flask_api/env/lib/python3.10/site-packages/jinja2/environment.py", line 1010, in get_template
    return self._load_template(name, globals)
  File "/Users/shuck/development/ML_flask_api/env/lib/python3.10/site-packages/jinja2/environment.py", line 969, in _load_template
    template = self.loader.load(self, name, self.make_globals(globals))
  File "/Users/shuck/development/ML_flask_api/env/lib/python3.10/site-packages/jinja2/loaders.py", line 138, in load
    code = environment.compile(source, name, filename)
  File "/Users/shuck/development/ML_flask_api/env/lib/python3.10/site-packages/jinja2/environment.py", line 768, in compile
    self.handle_exception(source=source_hint)
  File "/Users/shuck/development/ML_flask_api/env/lib/python3.10/site-packages/jinja2/environment.py", line 936, in handle_exception
    raise rewrite_traceback_stack(source=source)
  File "/Users/shuck/development/ML_flask_api/packages/ml_api/api/templates/home.html", line 15, in template
    {% comment %} fetch(apiUrl).then(response => {
jinja2.exceptions.TemplateSyntaxError: Encountered unknown tag 'comment'.
2022-10-04 11:58:24,984 — api.app — ERROR —log_exception:1741 — Exception on / [GET]
Traceback (most recent call last):
  File "/Users/shuck/development/ML_flask_api/env/lib/python3.10/site-packages/flask/app.py", line 2525, in wsgi_app
    response = self.full_dispatch_request()
  File "/Users/shuck/development/ML_flask_api/env/lib/python3.10/site-packages/flask/app.py", line 1822, in full_dispatch_request
    rv = self.handle_user_exception(e)
  File "/Users/shuck/development/ML_flask_api/env/lib/python3.10/site-packages/flask/app.py", line 1820, in full_dispatch_request
    rv = self.dispatch_request()
  File "/Users/shuck/development/ML_flask_api/env/lib/python3.10/site-packages/flask/app.py", line 1796, in dispatch_request
    return self.ensure_sync(self.view_functions[rule.endpoint])(**view_args)
  File "/Users/shuck/development/ML_flask_api/packages/ml_api/api/controller.py", line 18, in home
    return render_template('home.html')
  File "/Users/shuck/development/ML_flask_api/env/lib/python3.10/site-packages/flask/templating.py", line 146, in render_template
    template = app.jinja_env.get_or_select_template(template_name_or_list)
  File "/Users/shuck/development/ML_flask_api/env/lib/python3.10/site-packages/jinja2/environment.py", line 1081, in get_or_select_template
    return self.get_template(template_name_or_list, parent, globals)
  File "/Users/shuck/development/ML_flask_api/env/lib/python3.10/site-packages/jinja2/environment.py", line 1010, in get_template
    return self._load_template(name, globals)
  File "/Users/shuck/development/ML_flask_api/env/lib/python3.10/site-packages/jinja2/environment.py", line 969, in _load_template
    template = self.loader.load(self, name, self.make_globals(globals))
  File "/Users/shuck/development/ML_flask_api/env/lib/python3.10/site-packages/jinja2/loaders.py", line 138, in load
    code = environment.compile(source, name, filename)
  File "/Users/shuck/development/ML_flask_api/env/lib/python3.10/site-packages/jinja2/environment.py", line 768, in compile
    self.handle_exception(source=source_hint)
  File "/Users/shuck/development/ML_flask_api/env/lib/python3.10/site-packages/jinja2/environment.py", line 936, in handle_exception
    raise rewrite_traceback_stack(source=source)
  File "/Users/shuck/development/ML_flask_api/packages/ml_api/api/templates/home.html", line 14, in template
    {% comment %} fetch(apiUrl).then(response => {
jinja2.exceptions.TemplateSyntaxError: Encountered unknown tag 'comment'.
2022-10-04 11:58:25,915 — api.app — ERROR —log_exception:1741 — Exception on / [GET]
Traceback (most recent call last):
  File "/Users/shuck/development/ML_flask_api/env/lib/python3.10/site-packages/flask/app.py", line 2525, in wsgi_app
    response = self.full_dispatch_request()
  File "/Users/shuck/development/ML_flask_api/env/lib/python3.10/site-packages/flask/app.py", line 1822, in full_dispatch_request
    rv = self.handle_user_exception(e)
  File "/Users/shuck/development/ML_flask_api/env/lib/python3.10/site-packages/flask/app.py", line 1820, in full_dispatch_request
    rv = self.dispatch_request()
  File "/Users/shuck/development/ML_flask_api/env/lib/python3.10/site-packages/flask/app.py", line 1796, in dispatch_request
    return self.ensure_sync(self.view_functions[rule.endpoint])(**view_args)
  File "/Users/shuck/development/ML_flask_api/packages/ml_api/api/controller.py", line 18, in home
    return render_template('home.html')
  File "/Users/shuck/development/ML_flask_api/env/lib/python3.10/site-packages/flask/templating.py", line 146, in render_template
    template = app.jinja_env.get_or_select_template(template_name_or_list)
  File "/Users/shuck/development/ML_flask_api/env/lib/python3.10/site-packages/jinja2/environment.py", line 1081, in get_or_select_template
    return self.get_template(template_name_or_list, parent, globals)
  File "/Users/shuck/development/ML_flask_api/env/lib/python3.10/site-packages/jinja2/environment.py", line 1010, in get_template
    return self._load_template(name, globals)
  File "/Users/shuck/development/ML_flask_api/env/lib/python3.10/site-packages/jinja2/environment.py", line 969, in _load_template
    template = self.loader.load(self, name, self.make_globals(globals))
  File "/Users/shuck/development/ML_flask_api/env/lib/python3.10/site-packages/jinja2/loaders.py", line 138, in load
    code = environment.compile(source, name, filename)
  File "/Users/shuck/development/ML_flask_api/env/lib/python3.10/site-packages/jinja2/environment.py", line 768, in compile
    self.handle_exception(source=source_hint)
  File "/Users/shuck/development/ML_flask_api/env/lib/python3.10/site-packages/jinja2/environment.py", line 936, in handle_exception
    raise rewrite_traceback_stack(source=source)
  File "/Users/shuck/development/ML_flask_api/packages/ml_api/api/templates/home.html", line 14, in template
    {% comment %} fetch(apiUrl).then(response => {
jinja2.exceptions.TemplateSyntaxError: Encountered unknown tag 'comment'.
2022-10-04 11:58:26,568 — api.app — ERROR —log_exception:1741 — Exception on / [GET]
Traceback (most recent call last):
  File "/Users/shuck/development/ML_flask_api/env/lib/python3.10/site-packages/flask/app.py", line 2525, in wsgi_app
    response = self.full_dispatch_request()
  File "/Users/shuck/development/ML_flask_api/env/lib/python3.10/site-packages/flask/app.py", line 1822, in full_dispatch_request
    rv = self.handle_user_exception(e)
  File "/Users/shuck/development/ML_flask_api/env/lib/python3.10/site-packages/flask/app.py", line 1820, in full_dispatch_request
    rv = self.dispatch_request()
  File "/Users/shuck/development/ML_flask_api/env/lib/python3.10/site-packages/flask/app.py", line 1796, in dispatch_request
    return self.ensure_sync(self.view_functions[rule.endpoint])(**view_args)
  File "/Users/shuck/development/ML_flask_api/packages/ml_api/api/controller.py", line 18, in home
    return render_template('home.html')
  File "/Users/shuck/development/ML_flask_api/env/lib/python3.10/site-packages/flask/templating.py", line 146, in render_template
    template = app.jinja_env.get_or_select_template(template_name_or_list)
  File "/Users/shuck/development/ML_flask_api/env/lib/python3.10/site-packages/jinja2/environment.py", line 1081, in get_or_select_template
    return self.get_template(template_name_or_list, parent, globals)
  File "/Users/shuck/development/ML_flask_api/env/lib/python3.10/site-packages/jinja2/environment.py", line 1010, in get_template
    return self._load_template(name, globals)
  File "/Users/shuck/development/ML_flask_api/env/lib/python3.10/site-packages/jinja2/environment.py", line 969, in _load_template
    template = self.loader.load(self, name, self.make_globals(globals))
  File "/Users/shuck/development/ML_flask_api/env/lib/python3.10/site-packages/jinja2/loaders.py", line 138, in load
    code = environment.compile(source, name, filename)
  File "/Users/shuck/development/ML_flask_api/env/lib/python3.10/site-packages/jinja2/environment.py", line 768, in compile
    self.handle_exception(source=source_hint)
  File "/Users/shuck/development/ML_flask_api/env/lib/python3.10/site-packages/jinja2/environment.py", line 936, in handle_exception
    raise rewrite_traceback_stack(source=source)
  File "/Users/shuck/development/ML_flask_api/packages/ml_api/api/templates/home.html", line 14, in template
    {% comment %} fetch(apiUrl).then(response => {
jinja2.exceptions.TemplateSyntaxError: Encountered unknown tag 'comment'.
2022-10-04 11:58:27,100 — api.app — ERROR —log_exception:1741 — Exception on / [GET]
Traceback (most recent call last):
  File "/Users/shuck/development/ML_flask_api/env/lib/python3.10/site-packages/flask/app.py", line 2525, in wsgi_app
    response = self.full_dispatch_request()
  File "/Users/shuck/development/ML_flask_api/env/lib/python3.10/site-packages/flask/app.py", line 1822, in full_dispatch_request
    rv = self.handle_user_exception(e)
  File "/Users/shuck/development/ML_flask_api/env/lib/python3.10/site-packages/flask/app.py", line 1820, in full_dispatch_request
    rv = self.dispatch_request()
  File "/Users/shuck/development/ML_flask_api/env/lib/python3.10/site-packages/flask/app.py", line 1796, in dispatch_request
    return self.ensure_sync(self.view_functions[rule.endpoint])(**view_args)
  File "/Users/shuck/development/ML_flask_api/packages/ml_api/api/controller.py", line 18, in home
    return render_template('home.html')
  File "/Users/shuck/development/ML_flask_api/env/lib/python3.10/site-packages/flask/templating.py", line 146, in render_template
    template = app.jinja_env.get_or_select_template(template_name_or_list)
  File "/Users/shuck/development/ML_flask_api/env/lib/python3.10/site-packages/jinja2/environment.py", line 1081, in get_or_select_template
    return self.get_template(template_name_or_list, parent, globals)
  File "/Users/shuck/development/ML_flask_api/env/lib/python3.10/site-packages/jinja2/environment.py", line 1010, in get_template
    return self._load_template(name, globals)
  File "/Users/shuck/development/ML_flask_api/env/lib/python3.10/site-packages/jinja2/environment.py", line 969, in _load_template
    template = self.loader.load(self, name, self.make_globals(globals))
  File "/Users/shuck/development/ML_flask_api/env/lib/python3.10/site-packages/jinja2/loaders.py", line 138, in load
    code = environment.compile(source, name, filename)
  File "/Users/shuck/development/ML_flask_api/env/lib/python3.10/site-packages/jinja2/environment.py", line 768, in compile
    self.handle_exception(source=source_hint)
  File "/Users/shuck/development/ML_flask_api/env/lib/python3.10/site-packages/jinja2/environment.py", line 936, in handle_exception
    raise rewrite_traceback_stack(source=source)
  File "/Users/shuck/development/ML_flask_api/packages/ml_api/api/templates/home.html", line 14, in template
    {% comment %} fetch(apiUrl).then(response => {
jinja2.exceptions.TemplateSyntaxError: Encountered unknown tag 'comment'.
2022-10-04 11:58:27,514 — api.app — ERROR —log_exception:1741 — Exception on / [GET]
Traceback (most recent call last):
  File "/Users/shuck/development/ML_flask_api/env/lib/python3.10/site-packages/flask/app.py", line 2525, in wsgi_app
    response = self.full_dispatch_request()
  File "/Users/shuck/development/ML_flask_api/env/lib/python3.10/site-packages/flask/app.py", line 1822, in full_dispatch_request
    rv = self.handle_user_exception(e)
  File "/Users/shuck/development/ML_flask_api/env/lib/python3.10/site-packages/flask/app.py", line 1820, in full_dispatch_request
    rv = self.dispatch_request()
  File "/Users/shuck/development/ML_flask_api/env/lib/python3.10/site-packages/flask/app.py", line 1796, in dispatch_request
    return self.ensure_sync(self.view_functions[rule.endpoint])(**view_args)
  File "/Users/shuck/development/ML_flask_api/packages/ml_api/api/controller.py", line 18, in home
    return render_template('home.html')
  File "/Users/shuck/development/ML_flask_api/env/lib/python3.10/site-packages/flask/templating.py", line 146, in render_template
    template = app.jinja_env.get_or_select_template(template_name_or_list)
  File "/Users/shuck/development/ML_flask_api/env/lib/python3.10/site-packages/jinja2/environment.py", line 1081, in get_or_select_template
    return self.get_template(template_name_or_list, parent, globals)
  File "/Users/shuck/development/ML_flask_api/env/lib/python3.10/site-packages/jinja2/environment.py", line 1010, in get_template
    return self._load_template(name, globals)
  File "/Users/shuck/development/ML_flask_api/env/lib/python3.10/site-packages/jinja2/environment.py", line 969, in _load_template
    template = self.loader.load(self, name, self.make_globals(globals))
  File "/Users/shuck/development/ML_flask_api/env/lib/python3.10/site-packages/jinja2/loaders.py", line 138, in load
    code = environment.compile(source, name, filename)
  File "/Users/shuck/development/ML_flask_api/env/lib/python3.10/site-packages/jinja2/environment.py", line 768, in compile
    self.handle_exception(source=source_hint)
  File "/Users/shuck/development/ML_flask_api/env/lib/python3.10/site-packages/jinja2/environment.py", line 936, in handle_exception
    raise rewrite_traceback_stack(source=source)
  File "/Users/shuck/development/ML_flask_api/packages/ml_api/api/templates/home.html", line 14, in template
    {% comment %} fetch(apiUrl).then(response => {
jinja2.exceptions.TemplateSyntaxError: Encountered unknown tag 'comment'.
2022-10-04 13:16:42,336 — api.app — ERROR —log_exception:1741 — Exception on /predict [POST]
Traceback (most recent call last):
  File "/Users/shuck/development/ML_flask_api/env/lib/python3.10/site-packages/flask/app.py", line 2525, in wsgi_app
    response = self.full_dispatch_request()
  File "/Users/shuck/development/ML_flask_api/env/lib/python3.10/site-packages/flask/app.py", line 1822, in full_dispatch_request
    rv = self.handle_user_exception(e)
  File "/Users/shuck/development/ML_flask_api/env/lib/python3.10/site-packages/flask/app.py", line 1820, in full_dispatch_request
    rv = self.dispatch_request()
  File "/Users/shuck/development/ML_flask_api/env/lib/python3.10/site-packages/flask/app.py", line 1796, in dispatch_request
    return self.ensure_sync(self.view_functions[rule.endpoint])(**view_args)
  File "/Users/shuck/development/ML_flask_api/packages/ml_api/api/controller.py", line 75, in predict
    prediction_text="Water price is"+ json_data)
TypeError: can only concatenate str (not "dict") to str
2022-10-04 13:17:33,521 — api.app — ERROR —log_exception:1741 — Exception on /predict [POST]
Traceback (most recent call last):
  File "/Users/shuck/development/ML_flask_api/env/lib/python3.10/site-packages/flask/app.py", line 2525, in wsgi_app
    response = self.full_dispatch_request()
  File "/Users/shuck/development/ML_flask_api/env/lib/python3.10/site-packages/flask/app.py", line 1822, in full_dispatch_request
    rv = self.handle_user_exception(e)
  File "/Users/shuck/development/ML_flask_api/env/lib/python3.10/site-packages/flask/app.py", line 1820, in full_dispatch_request
    rv = self.dispatch_request()
  File "/Users/shuck/development/ML_flask_api/env/lib/python3.10/site-packages/flask/app.py", line 1796, in dispatch_request
    return self.ensure_sync(self.view_functions[rule.endpoint])(**view_args)
  File "/Users/shuck/development/ML_flask_api/packages/ml_api/api/controller.py", line 75, in predict
    prediction_text="Water price is"+ json_data["json_data"])
TypeError: can only concatenate str (not "int") to str
2022-10-04 13:27:26,242 — api.app — ERROR —log_exception:1741 — Exception on /predict [POST]
Traceback (most recent call last):
  File "/Users/shuck/development/ML_flask_api/env/lib/python3.10/site-packages/flask/app.py", line 2525, in wsgi_app
    response = self.full_dispatch_request()
  File "/Users/shuck/development/ML_flask_api/env/lib/python3.10/site-packages/flask/app.py", line 1822, in full_dispatch_request
    rv = self.handle_user_exception(e)
  File "/Users/shuck/development/ML_flask_api/env/lib/python3.10/site-packages/flask/app.py", line 1820, in full_dispatch_request
    rv = self.dispatch_request()
  File "/Users/shuck/development/ML_flask_api/env/lib/python3.10/site-packages/flask/app.py", line 1796, in dispatch_request
    return self.ensure_sync(self.view_functions[rule.endpoint])(**view_args)
  File "/Users/shuck/development/ML_flask_api/packages/ml_api/api/controller.py", line 75, in predict
    prediction_text="Water price is "+ str(json_data["json_data"]))
TypeError: string indices must be integers
2022-10-04 13:27:29,096 — api.app — ERROR —log_exception:1741 — Exception on /predict [POST]
Traceback (most recent call last):
  File "/Users/shuck/development/ML_flask_api/env/lib/python3.10/site-packages/flask/app.py", line 2525, in wsgi_app
    response = self.full_dispatch_request()
  File "/Users/shuck/development/ML_flask_api/env/lib/python3.10/site-packages/flask/app.py", line 1822, in full_dispatch_request
    rv = self.handle_user_exception(e)
  File "/Users/shuck/development/ML_flask_api/env/lib/python3.10/site-packages/flask/app.py", line 1820, in full_dispatch_request
    rv = self.dispatch_request()
  File "/Users/shuck/development/ML_flask_api/env/lib/python3.10/site-packages/flask/app.py", line 1796, in dispatch_request
    return self.ensure_sync(self.view_functions[rule.endpoint])(**view_args)
  File "/Users/shuck/development/ML_flask_api/packages/ml_api/api/controller.py", line 75, in predict
    prediction_text="Water price is "+ str(json_data["json_data"]))
TypeError: string indices must be integers
2022-10-04 13:28:28,944 — api.app — ERROR —log_exception:1741 — Exception on /predict [POST]
Traceback (most recent call last):
  File "/Users/shuck/development/ML_flask_api/env/lib/python3.10/site-packages/flask/app.py", line 2525, in wsgi_app
    response = self.full_dispatch_request()
  File "/Users/shuck/development/ML_flask_api/env/lib/python3.10/site-packages/flask/app.py", line 1822, in full_dispatch_request
    rv = self.handle_user_exception(e)
  File "/Users/shuck/development/ML_flask_api/env/lib/python3.10/site-packages/flask/app.py", line 1820, in full_dispatch_request
    rv = self.dispatch_request()
  File "/Users/shuck/development/ML_flask_api/env/lib/python3.10/site-packages/flask/app.py", line 1796, in dispatch_request
    return self.ensure_sync(self.view_functions[rule.endpoint])(**view_args)
  File "/Users/shuck/development/ML_flask_api/packages/ml_api/api/controller.py", line 75, in predict
    prediction_text="Water price is "+ str(json_data["json_data"]))
TypeError: string indices must be integers
2022-10-04 13:28:31,478 — api.app — ERROR —log_exception:1741 — Exception on /predict [POST]
Traceback (most recent call last):
  File "/Users/shuck/development/ML_flask_api/env/lib/python3.10/site-packages/flask/app.py", line 2525, in wsgi_app
    response = self.full_dispatch_request()
  File "/Users/shuck/development/ML_flask_api/env/lib/python3.10/site-packages/flask/app.py", line 1822, in full_dispatch_request
    rv = self.handle_user_exception(e)
  File "/Users/shuck/development/ML_flask_api/env/lib/python3.10/site-packages/flask/app.py", line 1820, in full_dispatch_request
    rv = self.dispatch_request()
  File "/Users/shuck/development/ML_flask_api/env/lib/python3.10/site-packages/flask/app.py", line 1796, in dispatch_request
    return self.ensure_sync(self.view_functions[rule.endpoint])(**view_args)
  File "/Users/shuck/development/ML_flask_api/packages/ml_api/api/controller.py", line 75, in predict
    prediction_text="Water price is "+ str(json_data["json_data"]))
TypeError: string indices must be integers
2022-10-04 13:29:36,302 — api.app — ERROR —log_exception:1741 — Exception on /predict [POST]
Traceback (most recent call last):
  File "/Users/shuck/development/ML_flask_api/env/lib/python3.10/site-packages/flask/app.py", line 2525, in wsgi_app
    response = self.full_dispatch_request()
  File "/Users/shuck/development/ML_flask_api/env/lib/python3.10/site-packages/flask/app.py", line 1822, in full_dispatch_request
    rv = self.handle_user_exception(e)
  File "/Users/shuck/development/ML_flask_api/env/lib/python3.10/site-packages/flask/app.py", line 1820, in full_dispatch_request
    rv = self.dispatch_request()
  File "/Users/shuck/development/ML_flask_api/env/lib/python3.10/site-packages/flask/app.py", line 1796, in dispatch_request
    return self.ensure_sync(self.view_functions[rule.endpoint])(**view_args)
  File "/Users/shuck/development/ML_flask_api/packages/ml_api/api/controller.py", line 75, in predict
    prediction_text="Water price is "+ str(json_data["json_data"]))
TypeError: string indices must be integers
2022-10-04 13:30:40,341 — api.app — ERROR —log_exception:1741 — Exception on /predict [POST]
Traceback (most recent call last):
  File "/Users/shuck/development/ML_flask_api/env/lib/python3.10/site-packages/flask/app.py", line 2525, in wsgi_app
    response = self.full_dispatch_request()
  File "/Users/shuck/development/ML_flask_api/env/lib/python3.10/site-packages/flask/app.py", line 1822, in full_dispatch_request
    rv = self.handle_user_exception(e)
  File "/Users/shuck/development/ML_flask_api/env/lib/python3.10/site-packages/flask/app.py", line 1820, in full_dispatch_request
    rv = self.dispatch_request()
  File "/Users/shuck/development/ML_flask_api/env/lib/python3.10/site-packages/flask/app.py", line 1796, in dispatch_request
    return self.ensure_sync(self.view_functions[rule.endpoint])(**view_args)
  File "/Users/shuck/development/ML_flask_api/packages/ml_api/api/controller.py", line 73, in predict
    return render_template(
TypeError: render_template() missing 1 required positional argument: 'template_name_or_list'
2022-10-04 13:31:48,303 — api.app — ERROR —log_exception:1741 — Exception on /predict [POST]
Traceback (most recent call last):
  File "/Users/shuck/development/ML_flask_api/env/lib/python3.10/site-packages/flask/app.py", line 2525, in wsgi_app
    response = self.full_dispatch_request()
  File "/Users/shuck/development/ML_flask_api/env/lib/python3.10/site-packages/flask/app.py", line 1822, in full_dispatch_request
    rv = self.handle_user_exception(e)
  File "/Users/shuck/development/ML_flask_api/env/lib/python3.10/site-packages/flask/app.py", line 1820, in full_dispatch_request
    rv = self.dispatch_request()
  File "/Users/shuck/development/ML_flask_api/env/lib/python3.10/site-packages/flask/app.py", line 1796, in dispatch_request
    return self.ensure_sync(self.view_functions[rule.endpoint])(**view_args)
  File "/Users/shuck/development/ML_flask_api/packages/ml_api/api/controller.py", line 73, in predict
    return render_template(
TypeError: render_template() missing 1 required positional argument: 'template_name_or_list'
2022-10-04 13:38:32,358 — api.app — ERROR —log_exception:1741 — Exception on /predict [GET]
Traceback (most recent call last):
  File "/Users/shuck/development/ML_flask_api/env/lib/python3.10/site-packages/flask/app.py", line 2525, in wsgi_app
    response = self.full_dispatch_request()
  File "/Users/shuck/development/ML_flask_api/env/lib/python3.10/site-packages/flask/app.py", line 1823, in full_dispatch_request
    return self.finalize_request(rv)
  File "/Users/shuck/development/ML_flask_api/env/lib/python3.10/site-packages/flask/app.py", line 1842, in finalize_request
    response = self.make_response(rv)
  File "/Users/shuck/development/ML_flask_api/env/lib/python3.10/site-packages/flask/app.py", line 2134, in make_response
    raise TypeError(
TypeError: The view function for 'prediction_app.predict' did not return a valid response. The function either returned None or ended without a return statement.
2022-10-04 13:39:22,915 — api.app — ERROR —log_exception:1741 — Exception on /predict [GET]
Traceback (most recent call last):
  File "/Users/shuck/development/ML_flask_api/env/lib/python3.10/site-packages/flask/app.py", line 2525, in wsgi_app
    response = self.full_dispatch_request()
  File "/Users/shuck/development/ML_flask_api/env/lib/python3.10/site-packages/flask/app.py", line 1823, in full_dispatch_request
    return self.finalize_request(rv)
  File "/Users/shuck/development/ML_flask_api/env/lib/python3.10/site-packages/flask/app.py", line 1842, in finalize_request
    response = self.make_response(rv)
  File "/Users/shuck/development/ML_flask_api/env/lib/python3.10/site-packages/flask/app.py", line 2134, in make_response
    raise TypeError(
TypeError: The view function for 'prediction_app.predict' did not return a valid response. The function either returned None or ended without a return statement.
2022-10-04 13:39:23,565 — api.app — ERROR —log_exception:1741 — Exception on /predict [GET]
Traceback (most recent call last):
  File "/Users/shuck/development/ML_flask_api/env/lib/python3.10/site-packages/flask/app.py", line 2525, in wsgi_app
    response = self.full_dispatch_request()
  File "/Users/shuck/development/ML_flask_api/env/lib/python3.10/site-packages/flask/app.py", line 1823, in full_dispatch_request
    return self.finalize_request(rv)
  File "/Users/shuck/development/ML_flask_api/env/lib/python3.10/site-packages/flask/app.py", line 1842, in finalize_request
    response = self.make_response(rv)
  File "/Users/shuck/development/ML_flask_api/env/lib/python3.10/site-packages/flask/app.py", line 2134, in make_response
    raise TypeError(
TypeError: The view function for 'prediction_app.predict' did not return a valid response. The function either returned None or ended without a return statement.
2022-10-04 13:39:23,776 — api.app — ERROR —log_exception:1741 — Exception on /predict [GET]
Traceback (most recent call last):
  File "/Users/shuck/development/ML_flask_api/env/lib/python3.10/site-packages/flask/app.py", line 2525, in wsgi_app
    response = self.full_dispatch_request()
  File "/Users/shuck/development/ML_flask_api/env/lib/python3.10/site-packages/flask/app.py", line 1823, in full_dispatch_request
    return self.finalize_request(rv)
  File "/Users/shuck/development/ML_flask_api/env/lib/python3.10/site-packages/flask/app.py", line 1842, in finalize_request
    response = self.make_response(rv)
  File "/Users/shuck/development/ML_flask_api/env/lib/python3.10/site-packages/flask/app.py", line 2134, in make_response
    raise TypeError(
TypeError: The view function for 'prediction_app.predict' did not return a valid response. The function either returned None or ended without a return statement.
2022-10-04 13:39:24,865 — api.app — ERROR —log_exception:1741 — Exception on /predict [GET]
Traceback (most recent call last):
  File "/Users/shuck/development/ML_flask_api/env/lib/python3.10/site-packages/flask/app.py", line 2525, in wsgi_app
    response = self.full_dispatch_request()
  File "/Users/shuck/development/ML_flask_api/env/lib/python3.10/site-packages/flask/app.py", line 1823, in full_dispatch_request
    return self.finalize_request(rv)
  File "/Users/shuck/development/ML_flask_api/env/lib/python3.10/site-packages/flask/app.py", line 1842, in finalize_request
    response = self.make_response(rv)
  File "/Users/shuck/development/ML_flask_api/env/lib/python3.10/site-packages/flask/app.py", line 2134, in make_response
    raise TypeError(
TypeError: The view function for 'prediction_app.predict' did not return a valid response. The function either returned None or ended without a return statement.
2022-10-04 13:46:13,650 — api.app — ERROR —log_exception:1741 — Exception on /predict [POST]
Traceback (most recent call last):
  File "/Users/shuck/development/ML_flask_api/env/lib/python3.10/site-packages/flask/app.py", line 2525, in wsgi_app
    response = self.full_dispatch_request()
  File "/Users/shuck/development/ML_flask_api/env/lib/python3.10/site-packages/flask/app.py", line 1823, in full_dispatch_request
    return self.finalize_request(rv)
  File "/Users/shuck/development/ML_flask_api/env/lib/python3.10/site-packages/flask/app.py", line 1842, in finalize_request
    response = self.make_response(rv)
  File "/Users/shuck/development/ML_flask_api/env/lib/python3.10/site-packages/flask/app.py", line 2134, in make_response
    raise TypeError(
TypeError: The view function for 'prediction_app.predict' did not return a valid response. The function either returned None or ended without a return statement.
2022-10-04 13:46:14,869 — api.app — ERROR —log_exception:1741 — Exception on /predict [POST]
Traceback (most recent call last):
  File "/Users/shuck/development/ML_flask_api/env/lib/python3.10/site-packages/flask/app.py", line 2525, in wsgi_app
    response = self.full_dispatch_request()
  File "/Users/shuck/development/ML_flask_api/env/lib/python3.10/site-packages/flask/app.py", line 1823, in full_dispatch_request
    return self.finalize_request(rv)
  File "/Users/shuck/development/ML_flask_api/env/lib/python3.10/site-packages/flask/app.py", line 1842, in finalize_request
    response = self.make_response(rv)
  File "/Users/shuck/development/ML_flask_api/env/lib/python3.10/site-packages/flask/app.py", line 2134, in make_response
    raise TypeError(
TypeError: The view function for 'prediction_app.predict' did not return a valid response. The function either returned None or ended without a return statement.
2022-10-04 13:46:18,511 — api.app — ERROR —log_exception:1741 — Exception on /predict [POST]
Traceback (most recent call last):
  File "/Users/shuck/development/ML_flask_api/env/lib/python3.10/site-packages/flask/app.py", line 2525, in wsgi_app
    response = self.full_dispatch_request()
  File "/Users/shuck/development/ML_flask_api/env/lib/python3.10/site-packages/flask/app.py", line 1823, in full_dispatch_request
    return self.finalize_request(rv)
  File "/Users/shuck/development/ML_flask_api/env/lib/python3.10/site-packages/flask/app.py", line 1842, in finalize_request
    response = self.make_response(rv)
  File "/Users/shuck/development/ML_flask_api/env/lib/python3.10/site-packages/flask/app.py", line 2134, in make_response
    raise TypeError(
TypeError: The view function for 'prediction_app.predict' did not return a valid response. The function either returned None or ended without a return statement.
2022-10-04 13:54:32,065 — api.app — ERROR —log_exception:1741 — Exception on /predict [GET]
Traceback (most recent call last):
  File "/Users/shuck/development/ML_flask_api/env/lib/python3.10/site-packages/flask/app.py", line 2525, in wsgi_app
    response = self.full_dispatch_request()
  File "/Users/shuck/development/ML_flask_api/env/lib/python3.10/site-packages/flask/app.py", line 1823, in full_dispatch_request
    return self.finalize_request(rv)
  File "/Users/shuck/development/ML_flask_api/env/lib/python3.10/site-packages/flask/app.py", line 1842, in finalize_request
    response = self.make_response(rv)
  File "/Users/shuck/development/ML_flask_api/env/lib/python3.10/site-packages/flask/app.py", line 2134, in make_response
    raise TypeError(
TypeError: The view function for 'prediction_app.predict' did not return a valid response. The function either returned None or ended without a return statement.
2022-10-04 13:54:36,776 — api.app — ERROR —log_exception:1741 — Exception on /predict [GET]
Traceback (most recent call last):
  File "/Users/shuck/development/ML_flask_api/env/lib/python3.10/site-packages/flask/app.py", line 2525, in wsgi_app
    response = self.full_dispatch_request()
  File "/Users/shuck/development/ML_flask_api/env/lib/python3.10/site-packages/flask/app.py", line 1823, in full_dispatch_request
    return self.finalize_request(rv)
  File "/Users/shuck/development/ML_flask_api/env/lib/python3.10/site-packages/flask/app.py", line 1842, in finalize_request
    response = self.make_response(rv)
  File "/Users/shuck/development/ML_flask_api/env/lib/python3.10/site-packages/flask/app.py", line 2134, in make_response
    raise TypeError(
TypeError: The view function for 'prediction_app.predict' did not return a valid response. The function either returned None or ended without a return statement.
2022-10-04 13:54:46,350 — api.app — ERROR —log_exception:1741 — Exception on /predict [GET]
Traceback (most recent call last):
  File "/Users/shuck/development/ML_flask_api/env/lib/python3.10/site-packages/flask/app.py", line 2525, in wsgi_app
    response = self.full_dispatch_request()
  File "/Users/shuck/development/ML_flask_api/env/lib/python3.10/site-packages/flask/app.py", line 1823, in full_dispatch_request
    return self.finalize_request(rv)
  File "/Users/shuck/development/ML_flask_api/env/lib/python3.10/site-packages/flask/app.py", line 1842, in finalize_request
    response = self.make_response(rv)
  File "/Users/shuck/development/ML_flask_api/env/lib/python3.10/site-packages/flask/app.py", line 2134, in make_response
    raise TypeError(
TypeError: The view function for 'prediction_app.predict' did not return a valid response. The function either returned None or ended without a return statement.
2022-10-04 13:54:48,540 — api.app — ERROR —log_exception:1741 — Exception on /predict [GET]
Traceback (most recent call last):
  File "/Users/shuck/development/ML_flask_api/env/lib/python3.10/site-packages/flask/app.py", line 2525, in wsgi_app
    response = self.full_dispatch_request()
  File "/Users/shuck/development/ML_flask_api/env/lib/python3.10/site-packages/flask/app.py", line 1823, in full_dispatch_request
    return self.finalize_request(rv)
  File "/Users/shuck/development/ML_flask_api/env/lib/python3.10/site-packages/flask/app.py", line 1842, in finalize_request
    response = self.make_response(rv)
  File "/Users/shuck/development/ML_flask_api/env/lib/python3.10/site-packages/flask/app.py", line 2134, in make_response
    raise TypeError(
TypeError: The view function for 'prediction_app.predict' did not return a valid response. The function either returned None or ended without a return statement.
